<robot name="onshape">
<link name="body_1">
<collision>
<origin xyz="0 0 0" rpy="0 -0 0" />
<geometry>
<mesh filename="package://body.stl"/>
</geometry>
<material name="body_material">
<color rgba="0.972549 0.529412 0.00392157 1.0"/>
</material>
</collision>
<collision>
<origin xyz="3.46945e-18 -0.0485 0.0143" rpy="0 -0 1.49355" />
<geometry>
<mesh filename="package://horn.stl"/>
</geometry>
<material name="horn_material">
<color rgba="0.917647 0.917647 0.917647 1.0"/>
</material>
</collision>
<collision>
<origin xyz="0.0485 4.33681e-18 0.0143" rpy="0 -0 -1.5708" />
<geometry>
<mesh filename="package://motor.stl"/>
</geometry>
<material name="motor_material">
<color rgba="0.470588 0.470588 0.470588 1.0"/>
</material>
</collision>
<collision>
<origin xyz="-0.0485 2.56739e-16 0.0143" rpy="6.87729e-22 3.74562e-16 1.5708" />
<geometry>
<mesh filename="package://motor.stl"/>
</geometry>
<material name="motor_material">
<color rgba="0.470588 0.470588 0.470588 1.0"/>
</material>
</collision>
<collision>
<origin xyz="0.0485 -1.94242e-17 0.0143" rpy="0 -0 1.45228" />
<geometry>
<mesh filename="package://horn.stl"/>
</geometry>
<material name="horn_material">
<color rgba="0.917647 0.917647 0.917647 1.0"/>
</material>
</collision>
<collision>
<origin xyz="-0.0485 6.93889e-17 0.0143" rpy="0 -0 1.49355" />
<geometry>
<mesh filename="package://horn.stl"/>
</geometry>
<material name="horn_material">
<color rgba="0.917647 0.917647 0.917647 1.0"/>
</material>
</collision>
<collision>
<origin xyz="-9.54098e-18 0.0485 0.0143" rpy="0 -0 8.32667e-16" />
<geometry>
<mesh filename="package://motor.stl"/>
</geometry>
<material name="motor_material">
<color rgba="0.470588 0.470588 0.470588 1.0"/>
</material>
</collision>
<collision>
<origin xyz="0 3.46945e-18 0.0286" rpy="3.14159 -0 0" />
<geometry>
<mesh filename="package://body.stl"/>
</geometry>
<material name="body_material">
<color rgba="0.972549 0.529412 0.00392157 1.0"/>
</material>
</collision>
<collision>
<origin xyz="1.73472e-18 -0.0485 0.0143" rpy="0 -0 -3.14159" />
<geometry>
<mesh filename="package://motor.stl"/>
</geometry>
<material name="motor_material">
<color rgba="0.470588 0.470588 0.470588 1.0"/>
</material>
</collision>
<collision>
<origin xyz="-9.66308e-18 0.0485 0.0143" rpy="0 -0 1.49355" />
<geometry>
<mesh filename="package://horn.stl"/>
</geometry>
<material name="horn_material">
<color rgba="0.917647 0.917647 0.917647 1.0"/>
</material>
</collision>
<visual>
<origin xyz="0 0 0" rpy="0 -0 0" />
<geometry>
<mesh filename="package://body_1.stl"/>
</geometry>
<material name="body_1_material">
<color rgba="0.546445 0.490703 0.424602 1.0"/>
</material>
</visual>
<inertial>
<origin xyz="-1.60686e-16 6.41819e-17 0.0143384" rpy="0 0 0"/>
<mass value="0.0808736" />
<inertia ixx="7.37408e-05" ixy="1.86671e-19"  ixz="-3.25773e-22" iyy="7.37408e-05" iyz="-2.0117e-21" izz="0.000135878" />
</inertial>
</link>

<link name="trunk">
<inertial>
<origin xyz="0 0 0" rpy="0 0 0" />
<mass value="1e-9" />
<inertia ixx="0" ixy="0" ixz="0" iyy="0" iyz="0" izz="0" />
</inertial>
</link>
<joint name="trunk_frame" type="floating">
<origin xyz="-1.46437e-18 8.91964e-20 0.0148" rpy="0 -0 0" />
<parent link="body_1" />
<child link="trunk" />
<axis xyz="0 0 0"/>
</joint>

<link name="doubleu_1">
<collision>
<origin xyz="4.93038e-32 -0.01615 0.018" rpy="0 1.09476e-47 0" />
<geometry>
<mesh filename="package://u.stl"/>
</geometry>
<material name="u_material">
<color rgba="0.972549 0.529412 0.00392157 1.0"/>
</material>
</collision>
<collision>
<origin xyz="2.50522e-17 -0.01615 0.0226" rpy="3.14159 4.93038e-32 1.5708" />
<geometry>
<mesh filename="package://u.stl"/>
</geometry>
<material name="u_material">
<color rgba="0.972549 0.529412 0.00392157 1.0"/>
</material>
</collision>
<visual>
<origin xyz="0 0 0" rpy="0 -0 0" />
<geometry>
<mesh filename="package://doubleu_1.stl"/>
</geometry>
<material name="doubleu_1_material">
<color rgba="0.972549 0.529412 0.00392157 1.0"/>
</material>
</visual>
<inertial>
<origin xyz="1.5043e-17 -0.01615 0.0203" rpy="0 0 0"/>
<mass value="0.00830698" />
<inertia ixx="2.78361e-06" ixy="-2.7377e-22"  ixz="-1.07572e-21" iyy="2.78361e-06" iyz="-4.53885e-22" izz="1.9255e-06" />
</inertial>
</link>

<link name="platesblock_1">
<collision>
<origin xyz="1.37911e-15 -0.063 0.015" rpy="1.30136e-16 1.57211e-15 -2.55772" />
<geometry>
<mesh filename="package://horn.stl"/>
</geometry>
<material name="horn_material">
<color rgba="0.917647 0.917647 0.917647 1.0"/>
</material>
</collision>
<collision>
<origin xyz="0 0 0.015" rpy="-1.08551e-32 -0 0" />
<geometry>
<mesh filename="package://horn.stl"/>
</geometry>
<material name="horn_material">
<color rgba="0.917647 0.917647 0.917647 1.0"/>
</material>
</collision>
<collision>
<origin xyz="1.42074e-15 -0.063 0.015" rpy="-1.33671e-15 1.74617e-15 -3.14159" />
<geometry>
<mesh filename="package://motor.stl"/>
</geometry>
<material name="motor_material">
<color rgba="0.470588 0.470588 0.470588 1.0"/>
</material>
</collision>
<collision>
<origin xyz="-2.77556e-17 1.38778e-17 0.015" rpy="2.3574e-16 -1.52412e-15 -1.45338e-16" />
<geometry>
<mesh filename="package://motor.stl"/>
</geometry>
<material name="motor_material">
<color rgba="0.470588 0.470588 0.470588 1.0"/>
</material>
</collision>
<collision>
<origin xyz="0.0143 0.006 0.015" rpy="1.5708 1.42923e-15 -1.5708" />
<geometry>
<mesh filename="package://plate.stl"/>
</geometry>
<material name="plate_material">
<color rgba="0.972549 0.529412 0.00392157 1.0"/>
</material>
</collision>
<collision>
<origin xyz="-0.012 0.006 0.015" rpy="1.5708 3.74518e-16 -1.5708" />
<geometry>
<mesh filename="package://plate.stl"/>
</geometry>
<material name="plate_material">
<color rgba="0.972549 0.529412 0.00392157 1.0"/>
</material>
</collision>
<visual>
<origin xyz="0 0 0" rpy="0 -0 0" />
<geometry>
<mesh filename="package://platesblock_1.stl"/>
</geometry>
<material name="platesblock_1_material">
<color rgba="0.5601 0.491944 0.411121 1.0"/>
</material>
</visual>
<inertial>
<origin xyz="6.99273e-16 -0.0315 0.0150372" rpy="0 0 0"/>
<mass value="0.0417755" />
<inertia ixx="2.96153e-05" ixy="-2.99773e-12"  ixz="-4.53853e-21" iyy="7.457e-06" iyz="-3.74428e-20" izz="2.73625e-05" />
</inertial>
</link>

<link name="leg_1">
<collision>
<origin xyz="0 0.015 0" rpy="-1.16022e-32 -0 0" />
<geometry>
<mesh filename="package://leg.stl"/>
</geometry>
<material name="leg_material">
<color rgba="0.972549 0.529412 0.00392157 1.0"/>
</material>
</collision>
<visual>
<origin xyz="0 0 0" rpy="0 -0 0" />
<geometry>
<mesh filename="package://leg_1.stl"/>
</geometry>
<material name="leg_1_material">
<color rgba="0.972549 0.529412 0.00392157 1.0"/>
</material>
</visual>
<inertial>
<origin xyz="-1.81218e-17 0.015 -0.0533786" rpy="0 0 0"/>
<mass value="0.0154162" />
<inertia ixx="2.13816e-05" ixy="0"  ixz="0" iyy="1.88204e-05" iyz="-3.52662e-38" izz="3.58407e-06" />
</inertial>
</link>

<joint name="leg1_c" type="revolute">
<origin xyz="1.36696e-15 -0.063 -1.56125e-17" rpy="1.5708 7.3803e-16 3.14159" />
<parent link="platesblock_1" />
<child link="leg_1" />
<axis xyz="0 1 0"/>
<limit effort="1" velocity="20" />
<joint_properties friction="0.0"/>
</joint>

<joint name="leg1_b" type="revolute">
<origin xyz="0.015 -0.01615 0.0406" rpy="-1.5708 4.21149e-16 1.5708" />
<parent link="doubleu_1" />
<child link="platesblock_1" />
<axis xyz="0 0 1"/>
<limit effort="1" velocity="20" />
<joint_properties friction="0.0"/>
</joint>

<joint name="leg1_a" type="revolute">
<origin xyz="-0.0485 2.51367e-16 -0.0007" rpy="-1.5708 3.03402e-16 1.5708" />
<parent link="body_1" />
<child link="doubleu_1" />
<axis xyz="0 1 0"/>
<limit effort="1" velocity="20" />
<joint_properties friction="0.0"/>
</joint>

<link name="doubleu_2">
<collision>
<origin xyz="7.70372e-34 -0.015 0.018" rpy="0 6.10877e-48 0" />
<geometry>
<mesh filename="package://u.stl"/>
</geometry>
<material name="u_material">
<color rgba="0.972549 0.529412 0.00392157 1.0"/>
</material>
</collision>
<collision>
<origin xyz="6.28584e-17 -0.015 0.0226" rpy="3.14159 -1.95509e-20 1.5708" />
<geometry>
<mesh filename="package://u.stl"/>
</geometry>
<material name="u_material">
<color rgba="0.972549 0.529412 0.00392157 1.0"/>
</material>
</collision>
<visual>
<origin xyz="0 0 0" rpy="0 -0 0" />
<geometry>
<mesh filename="package://doubleu_2.stl"/>
</geometry>
<material name="doubleu_2_material">
<color rgba="0.972549 0.529412 0.00392157 1.0"/>
</material>
</visual>
<inertial>
<origin xyz="3.41219e-17 -0.015 0.0203" rpy="0 0 0"/>
<mass value="0.00830698" />
<inertia ixx="2.78361e-06" ixy="-3.20957e-22"  ixz="-2.77828e-21" iyy="2.78361e-06" iyz="-1.53554e-22" izz="1.9255e-06" />
</inertial>
</link>

<link name="platesblock_2">
<collision>
<origin xyz="0.006 0.012 0.015" rpy="1.5708 7.49401e-16 3.14159" />
<geometry>
<mesh filename="package://plate.stl"/>
</geometry>
<material name="plate_material">
<color rgba="0.972549 0.529412 0.00392157 1.0"/>
</material>
</collision>
<collision>
<origin xyz="0.006 -0.0143 0.015" rpy="1.5708 3.26128e-15 -3.14159" />
<geometry>
<mesh filename="package://plate.stl"/>
</geometry>
<material name="plate_material">
<color rgba="0.972549 0.529412 0.00392157 1.0"/>
</material>
</collision>
<collision>
<origin xyz="-0.063 -1.53176e-15 0.015" rpy="-4.63279e-15 2.96691e-15 1.87535" />
<geometry>
<mesh filename="package://horn.stl"/>
</geometry>
<material name="horn_material">
<color rgba="0.917647 0.917647 0.917647 1.0"/>
</material>
</collision>
<collision>
<origin xyz="0 0 0.015" rpy="0 -1.09308e-31 0" />
<geometry>
<mesh filename="package://horn.stl"/>
</geometry>
<material name="horn_material">
<color rgba="0.917647 0.917647 0.917647 1.0"/>
</material>
</collision>
<collision>
<origin xyz="-0.063 -1.5335e-15 0.015" rpy="-5.34757e-15 1.42889e-15 1.5708" />
<geometry>
<mesh filename="package://motor.stl"/>
</geometry>
<material name="motor_material">
<color rgba="0.470588 0.470588 0.470588 1.0"/>
</material>
</collision>
<collision>
<origin xyz="0 0 0.015" rpy="3.26128e-15 -1.42889e-15 -1.5708" />
<geometry>
<mesh filename="package://motor.stl"/>
</geometry>
<material name="motor_material">
<color rgba="0.470588 0.470588 0.470588 1.0"/>
</material>
</collision>
<visual>
<origin xyz="0 0 0" rpy="0 -0 0" />
<geometry>
<mesh filename="package://platesblock_2.stl"/>
</geometry>
<material name="platesblock_2_material">
<color rgba="0.5601 0.491944 0.411121 1.0"/>
</material>
</visual>
<inertial>
<origin xyz="-0.0315 -7.538e-16 0.0150372" rpy="0 0 0"/>
<mass value="0.0417755" />
<inertia ixx="4.6241e-06" ixy="2.99773e-12"  ixz="-1.36081e-19" iyy="2.98279e-05" iyz="-1.12764e-20" izz="2.99828e-05" />
</inertial>
</link>

<link name="leg_2">
<collision>
<origin xyz="0 0.015 0" rpy="-1.80688e-31 -0 0" />
<geometry>
<mesh filename="package://leg.stl"/>
</geometry>
<material name="leg_material">
<color rgba="0.972549 0.529412 0.00392157 1.0"/>
</material>
</collision>
<visual>
<origin xyz="0 0 0" rpy="0 -0 0" />
<geometry>
<mesh filename="package://leg_2.stl"/>
</geometry>
<material name="leg_2_material">
<color rgba="0.972549 0.529412 0.00392157 1.0"/>
</material>
</visual>
<inertial>
<origin xyz="-1.81218e-17 0.015 -0.0533786" rpy="0 0 0"/>
<mass value="0.0154162" />
<inertia ixx="2.13816e-05" ixy="0"  ixz="0" iyy="1.88204e-05" iyz="-1.21392e-36" izz="3.58407e-06" />
</inertial>
</link>

<joint name="leg2_c" type="revolute">
<origin xyz="-0.063 -1.53176e-15 7.28584e-17" rpy="1.5708 1.64389e-15 1.5708" />
<parent link="platesblock_2" />
<child link="leg_2" />
<axis xyz="0 1 0"/>
<limit effort="1" velocity="20" />
<joint_properties friction="0.0"/>
</joint>

<joint name="leg2_b" type="revolute">
<origin xyz="0.015 -0.015 0.0406" rpy="3.14159 1.5708 0" />
<parent link="doubleu_2" />
<child link="platesblock_2" />
<axis xyz="0 0 1"/>
<limit effort="1" velocity="20" />
<joint_properties friction="0.0"/>
</joint>

<joint name="leg2_a" type="revolute">
<origin xyz="-3.78517e-18 -0.0485 -0.0007" rpy="-1.5708 5.02497e-24 -3.14159" />
<parent link="body_1" />
<child link="doubleu_2" />
<axis xyz="0 1 0"/>
<limit effort="1" velocity="20" />
<joint_properties friction="0.0"/>
</joint>

<link name="doubleu_3">
<collision>
<origin xyz="6.93889e-18 0.01615 0.0226" rpy="-3.14159 -1.03799e-25 1.5708" />
<geometry>
<mesh filename="package://u.stl"/>
</geometry>
<material name="u_material">
<color rgba="0.972549 0.529412 0.00392157 1.0"/>
</material>
</collision>
<collision>
<origin xyz="-7.70372e-34 0.01615 0.018" rpy="0 -0 0" />
<geometry>
<mesh filename="package://u.stl"/>
</geometry>
<material name="u_material">
<color rgba="0.972549 0.529412 0.00392157 1.0"/>
</material>
</collision>
<visual>
<origin xyz="0 0 0" rpy="0 -0 0" />
<geometry>
<mesh filename="package://doubleu_3.stl"/>
</geometry>
<material name="doubleu_3_material">
<color rgba="0.972549 0.529412 0.00392157 1.0"/>
</material>
</visual>
<inertial>
<origin xyz="6.22071e-18 0.01615 0.0203" rpy="0 0 0"/>
<mass value="0.00830698" />
<inertia ixx="2.78361e-06" ixy="-3.11521e-22"  ixz="-2.8844e-22" iyy="2.78361e-06" iyz="-4.51044e-22" izz="1.9255e-06" />
</inertial>
</link>

<link name="platesblock_3">
<collision>
<origin xyz="0.006 0.012 0.015" rpy="1.5708 7.21645e-16 3.14159" />
<geometry>
<mesh filename="package://plate.stl"/>
</geometry>
<material name="plate_material">
<color rgba="0.972549 0.529412 0.00392157 1.0"/>
</material>
</collision>
<collision>
<origin xyz="-0.063 -1.37217e-15 0.015" rpy="-4.06157e-15 -1.10428e-17 1.5708" />
<geometry>
<mesh filename="package://motor.stl"/>
</geometry>
<material name="motor_material">
<color rgba="0.470588 0.470588 0.470588 1.0"/>
</material>
</collision>
<collision>
<origin xyz="0 -1.73472e-18 0.015" rpy="4.85723e-16 1.10428e-17 -1.5708" />
<geometry>
<mesh filename="package://motor.stl"/>
</geometry>
<material name="motor_material">
<color rgba="0.470588 0.470588 0.470588 1.0"/>
</material>
</collision>
<collision>
<origin xyz="-0.063 -1.37217e-15 0.015" rpy="-3.1657e-16 3.81975e-15 3.06435" />
<geometry>
<mesh filename="package://horn.stl"/>
</geometry>
<material name="horn_material">
<color rgba="0.917647 0.917647 0.917647 1.0"/>
</material>
</collision>
<collision>
<origin xyz="0.006 -0.0143 0.015" rpy="1.5708 1.19349e-15 -3.14159" />
<geometry>
<mesh filename="package://plate.stl"/>
</geometry>
<material name="plate_material">
<color rgba="0.972549 0.529412 0.00392157 1.0"/>
</material>
</collision>
<collision>
<origin xyz="0 0 0.015" rpy="0 -1.11266e-32 0" />
<geometry>
<mesh filename="package://horn.stl"/>
</geometry>
<material name="horn_material">
<color rgba="0.917647 0.917647 0.917647 1.0"/>
</material>
</collision>
<visual>
<origin xyz="0 0 0" rpy="0 -0 0" />
<geometry>
<mesh filename="package://platesblock_3.stl"/>
</geometry>
<material name="platesblock_3_material">
<color rgba="0.5601 0.491944 0.411121 1.0"/>
</material>
</visual>
<inertial>
<origin xyz="-0.0315 -6.84851e-16 0.0150372" rpy="0 0 0"/>
<mass value="0.0417755" />
<inertia ixx="4.6241e-06" ixy="2.99773e-12"  ixz="-2.05405e-20" iyy="2.98279e-05" iyz="8.95618e-21" izz="2.99828e-05" />
</inertial>
</link>

<link name="leg_3">
<collision>
<origin xyz="0 0.015 -2.77556e-17" rpy="-1.70001e-31 -4.93038e-32 -9.86076e-32" />
<geometry>
<mesh filename="package://leg.stl"/>
</geometry>
<material name="leg_material">
<color rgba="0.972549 0.529412 0.00392157 1.0"/>
</material>
</collision>
<visual>
<origin xyz="0 0 0" rpy="0 -0 0" />
<geometry>
<mesh filename="package://leg_3.stl"/>
</geometry>
<material name="leg_3_material">
<color rgba="0.972549 0.529412 0.00392157 1.0"/>
</material>
</visual>
<inertial>
<origin xyz="-1.81218e-17 0.015 -0.0533786" rpy="0 0 0"/>
<mass value="0.0154162" />
<inertia ixx="2.13816e-05" ixy="-1.85583e-36"  ixz="-8.25685e-36" iyy="1.88204e-05" iyz="2.87833e-37" izz="3.58407e-06" />
</inertial>
</link>

<link name="tip">
<inertial>
<origin xyz="0 0 0" rpy="0 0 0" />
<mass value="1e-9" />
<inertia ixx="0" ixy="0" ixz="0" iyy="0" iyz="0" izz="0" />
</inertial>
</link>
<joint name="tip_frame" type="floating">
<origin xyz="0.0025 0.015 -0.1005" rpy="1.97215e-31 1.5708 0" />
<parent link="leg_3" />
<child link="tip" />
<axis xyz="0 0 0"/>
</joint>

<joint name="leg3_c" type="revolute">
<origin xyz="-0.063 -1.37217e-15 -5.55112e-17" rpy="1.5708 1.28111e-16 1.5708" />
<parent link="platesblock_3" />
<child link="leg_3" />
<axis xyz="0 1 0"/>
<limit effort="1" velocity="20" />
<joint_properties friction="0.0"/>
</joint>

<joint name="leg3_b" type="revolute">
<origin xyz="-0.015 0.01615 0.0406" rpy="-4.58992e-16 1.5708 0" />
<parent link="doubleu_3" />
<child link="platesblock_3" />
<axis xyz="0 0 1"/>
<limit effort="1" velocity="20" />
<joint_properties friction="0.0"/>
</joint>

<joint name="leg3_a" type="revolute">
<origin xyz="0.0485 5.20417e-18 -0.0007" rpy="1.5708 -4.93038e-32 1.5708" />
<parent link="body_1" />
<child link="doubleu_3" />
<axis xyz="0 -1 0"/>
<limit effort="1" velocity="20" />
<joint_properties friction="0.0"/>
</joint>

<link name="doubleu_4">
<collision>
<origin xyz="6.16298e-33 0.01615 0.018" rpy="0 6.75266e-40 0" />
<geometry>
<mesh filename="package://u.stl"/>
</geometry>
<material name="u_material">
<color rgba="0.972549 0.529412 0.00392157 1.0"/>
</material>
</collision>
<collision>
<origin xyz="4.08389e-17 0.01615 0.0226" rpy="-3.14159 5.55166e-17 1.5708" />
<geometry>
<mesh filename="package://u.stl"/>
</geometry>
<material name="u_material">
<color rgba="0.972549 0.529412 0.00392157 1.0"/>
</material>
</collision>
<visual>
<origin xyz="0 0 0" rpy="0 -0 0" />
<geometry>
<mesh filename="package://doubleu_4.stl"/>
</geometry>
<material name="doubleu_4_material">
<color rgba="0.972549 0.529412 0.00392157 1.0"/>
</material>
</visual>
<inertial>
<origin xyz="2.31121e-17 0.01615 0.0203" rpy="0 0 0"/>
<mass value="0.00830698" />
<inertia ixx="2.78361e-06" ixy="-2.67378e-22"  ixz="-1.74233e-21" iyy="2.78361e-06" iyz="-2.65509e-22" izz="1.9255e-06" />
</inertial>
</link>

<link name="platesblock_4">
<collision>
<origin xyz="0.006 0.012 0.0135" rpy="1.5708 1.73472e-15 3.14159" />
<geometry>
<mesh filename="package://plate.stl"/>
</geometry>
<material name="plate_material">
<color rgba="0.972549 0.529412 0.00392157 1.0"/>
</material>
</collision>
<collision>
<origin xyz="0.006 -0.0143 0.0135" rpy="1.5708 1.27676e-15 3.14159" />
<geometry>
<mesh filename="package://plate.stl"/>
</geometry>
<material name="plate_material">
<color rgba="0.972549 0.529412 0.00392157 1.0"/>
</material>
</collision>
<collision>
<origin xyz="0 0 0.0135" rpy="0 -1.09856e-31 0" />
<geometry>
<mesh filename="package://horn.stl"/>
</geometry>
<material name="horn_material">
<color rgba="0.917647 0.917647 0.917647 1.0"/>
</material>
</collision>
<collision>
<origin xyz="-0.063 -1.34268e-15 0.0135" rpy="3.01958e-15 -8.49786e-16 -1.83339" />
<geometry>
<mesh filename="package://horn.stl"/>
</geometry>
<material name="horn_material">
<color rgba="0.917647 0.917647 0.917647 1.0"/>
</material>
</collision>
<collision>
<origin xyz="-1.38778e-17 -1.73472e-18 0.0135" rpy="2.93284e-15 -3.66174e-17 -1.5708" />
<geometry>
<mesh filename="package://motor.stl"/>
</geometry>
<material name="motor_material">
<color rgba="0.470588 0.470588 0.470588 1.0"/>
</material>
</collision>
<collision>
<origin xyz="-0.063 -1.34441e-15 0.0135" rpy="-3.09012e-15 3.66174e-17 1.5708" />
<geometry>
<mesh filename="package://motor.stl"/>
</geometry>
<material name="motor_material">
<color rgba="0.470588 0.470588 0.470588 1.0"/>
</material>
</collision>
<visual>
<origin xyz="0 0 0" rpy="0 -0 0" />
<geometry>
<mesh filename="package://platesblock_4.stl"/>
</geometry>
<material name="platesblock_4_material">
<color rgba="0.5601 0.491944 0.411121 1.0"/>
</material>
</visual>
<inertial>
<origin xyz="-0.0315 -6.68603e-16 0.0135372" rpy="0 0 0"/>
<mass value="0.0417755" />
<inertia ixx="4.6241e-06" ixy="2.99773e-12"  ixz="-2.26052e-20" iyy="2.98279e-05" iyz="2.49351e-21" izz="2.99828e-05" />
</inertial>
</link>

<link name="leg_4">
<collision>
<origin xyz="0 -0.015 0" rpy="-1.17202e-31 -0 -4.93038e-32" />
<geometry>
<mesh filename="package://leg.stl"/>
</geometry>
<material name="leg_material">
<color rgba="0.972549 0.529412 0.00392157 1.0"/>
</material>
</collision>
<visual>
<origin xyz="0 0 0" rpy="0 -0 0" />
<geometry>
<mesh filename="package://leg_4.stl"/>
</geometry>
<material name="leg_4_material">
<color rgba="0.972549 0.529412 0.00392157 1.0"/>
</material>
</visual>
<inertial>
<origin xyz="-1.81218e-17 -0.015 -0.0533786" rpy="0 0 0"/>
<mass value="0.0154162" />
<inertia ixx="2.13816e-05" ixy="-1.98211e-36"  ixz="4.73036e-67" iyy="1.88204e-05" iyz="-1.00144e-35" izz="3.58407e-06" />
</inertial>
</link>

<joint name="leg4_c" type="revolute">
<origin xyz="-0.063 -1.34268e-15 -0.0015" rpy="-1.5708 -6.75802e-18 -1.5708" />
<parent link="platesblock_4" />
<child link="leg_4" />
<axis xyz="0 -1 0"/>
<limit effort="1" velocity="20" />
<joint_properties friction="0.0"/>
</joint>

<joint name="leg4_b" type="revolute">
<origin xyz="-0.015 0.01615 0.0406" rpy="-3.69196e-16 1.5708 0" />
<parent link="doubleu_4" />
<child link="platesblock_4" />
<axis xyz="0 0 1"/>
<limit effort="1" velocity="20" />
<joint_properties friction="0.0"/>
</joint>

<joint name="leg4_a" type="revolute">
<origin xyz="-9.72372e-18 0.0485 -0.0007" rpy="1.5708 5.00173e-19 -3.14159" />
<parent link="body_1" />
<child link="doubleu_4" />
<axis xyz="0 -1 0"/>
<limit effort="1" velocity="20" />
<joint_properties friction="0.0"/>
</joint>


</robot>
